<?xml version="1.0"?>

<robot name="ur3" xmlns:xacro="http://www.ros.org/wiki/xacro">
  <link name="base_link" >
    <visual>
      <origin xyz="0 0 0" rpy="0 0 3.14"/>
      <geometry>
        <mesh filename="visual/base.dae"/>
      </geometry>
      <material name="LightGrey">
        <color rgba="0.7 0.7 0.7 1.0"/>
      </material>
    </visual>
    <collision>
      <geometry>
        <mesh filename="collision/base.stl"/>
      </geometry>
    </collision>      
    <inertial>
      <mass value="2.0" />
      <origin xyz="0.0 0.0 0.0" rpy="0 0 3.14" />
      <inertia ixx="0.0030531654454" ixy="0.0" ixz="0.0"
        iyy="0.0030531654454" iyz="0.0"
        izz="0.005625" />
    </inertial>
  </link>

  <joint name="shoulder_pan_joint" type="revolute">
    <parent link="base_link" />
    <child link = "shoulder_link" />
    <origin xyz="0.0 0.0 0.1519" rpy="0.0 0.0 0.0" />
    <axis xyz="0 0 1" />
    <limit lower="-6.28" upper="6.28" effort="56.0" velocity="3.14"/>
    <dynamics damping="0.0" friction="0.0"/>
  </joint>

  <link name="shoulder_link">
    <visual>
      <origin xyz="0.0 0.0 0.0" rpy="0 0 3.14" />
      <geometry>
        <mesh filename="visual/shoulder.dae"/>
      </geometry>
      <material name="LightGrey">
        <color rgba="0.7 0.7 0.7 1.0"/>
      </material>
    </visual>
    <collision>
      <geometry>
        <mesh filename="collision/shoulder.stl"/>
      </geometry>
    </collision>
    <inertial>
      <mass value="2.0" />
      <origin xyz="0.0 0.0 0.0" rpy="0 0 3.14" />
      <inertia ixx="0.008093163429399999" ixy="0.0" ixz="0.0"
        iyy="0.008093163429399999" iyz="0.0"
        izz="0.005625" />
    </inertial>
  </link>

  <joint name="shoulder_lift_joint" type="revolute">
    <parent link="shoulder_link" />
    <child link = "upper_arm_link" />
    <origin xyz="0.0 0.0 0.0" rpy="1.57 0.0 0.0" />
    <axis xyz="0 0 1" />
    <limit lower="-6.28" upper="6.28" effort="56.0" velocity="3.14"/>
    <dynamics damping="0.0" friction="0.0"/>
  </joint>

  <link name="upper_arm_link">
    <visual>
      <origin xyz="0 0 0.1198" rpy="1.57 0 -1.57"/>
      <geometry>
        <mesh filename="visual/upperarm.dae"/>
      </geometry>
      <material name="LightGrey">
        <color rgba="0.7 0.7 0.7 1.0"/>
      </material>
    </visual>
    <collision>
      <origin xyz="0 0 0.1198" rpy="1.57 0 -1.57"/>
      <geometry>
        <mesh filename="collision/upperarm.stl"/>
      </geometry>
    </collision>
    <inertial>
      <mass value="3.42" />
      <origin xyz="0.0 0.0 0.121825" rpy="0 0 0" />
      <inertia ixx="0.021728483221103233" ixy="0.0" ixz="0.0"
        iyy="0.021728483221103233" iyz="0.0"
        izz="0.00961875" />
    </inertial>
  </link>

  <joint name="elbow_joint" type="revolute">
    <parent link="upper_arm_link" />
    <child link = "forearm_link" />
    <origin xyz="-0.24365 0.0 0.0" rpy="0.0 0.0 0.0" />
    <axis xyz="0 0 1"/>
    <limit lower="-3.14" upper="3.14" effort="28.0" velocity="3.14"/>
    <dynamics damping="0.0" friction="0.0"/>
  </joint>

  <link name="forearm_link">
    <visual>
        <origin xyz="0 0 0.0275" rpy="1.57 0 -1.57"/>
        <geometry>
        <mesh filename="visual/forearm.dae"/>
      </geometry>
      <material name="LightGrey">
        <color rgba="0.7 0.7 0.7 1.0"/>
      </material>
    </visual>
    <collision>
      <origin xyz="0 0 0.0275" rpy="1.57 0 -1.57"/>
      <geometry>
        <mesh filename="collision/forearm.stl"/>
      </geometry>
    </collision>
    <inertial>
      <mass value="1.26" />
      <origin xyz="0.0 0.0 0.106625" rpy="0 0 0" />
      <inertia ixx="0.006546806443776375" ixy="0.0" ixz="0.0"
        iyy="0.006546806443776375" iyz="0.0"
        izz="0.00354375" />
    </inertial>
  </link>

  <joint name="wrist_1_joint" type="revolute">
    <parent link="forearm_link" />
    <child link = "wrist_1_link" />
    <origin xyz="-0.21325 0.0 0.11235" rpy="0.0 0.0 0.0" />
    <axis xyz="0 0 1" />
    <limit lower="-6.28" upper="6.28" effort="12.0" velocity="6.28"/>
    <dynamics damping="0.0" friction="0.0"/>
  </joint>

  <link name="wrist_1_link">
    <visual>
      <origin xyz="0 0 -0.085" rpy="1.57 0 0"/>
      <geometry>
        <mesh filename="visual/wrist1.dae"/>
      </geometry>
      <material name="LightGrey">
        <color rgba="0.7 0.7 0.7 1.0"/>
      </material>
    </visual>
    <collision>
      <origin xyz="0 0 -0.085" rpy="1.57 0 0"/>
      <geometry>
        <mesh filename="collision/wrist1.stl"/>
      </geometry>
    </collision>
    <inertial>
      <mass value="0.8" />
      <origin xyz="0.0 0.08505 0.0" rpy="0 0 0" />
      <inertia ixx="0.002084999166" ixy="0.0" ixz="0.0"
        iyy="0.002084999166" iyz="0.0"
        izz="0.00225" />
    </inertial>
  </link>

  <joint name="wrist_2_joint" type="revolute">
    <parent link="wrist_1_link" />
    <child link = "wrist_2_link" />
    <origin xyz="0.0 -0.08535 0.0" rpy="1.57 0.0 0.0" />
    <axis xyz="0 0 1" />
    <limit lower="-6.28" upper="6.28" effort="12.0" velocity="6.28"/>
    <dynamics damping="0.0" friction="0.0"/>
  </joint>

  <link name="wrist_2_link">
    <visual>
      <origin xyz="0 0 -0.085" rpy="0 0 0"/>
      <geometry>
        <mesh filename="visual/wrist2.dae"/>
      </geometry>
      <material name="LightGrey">
        <color rgba="0.7 0.7 0.7 1.0"/>
      </material>
    </visual>
    <collision>
      <origin xyz="0 0 -0.085" rpy="0 0 0"/>
      <geometry>
        <mesh filename="collision/wrist2.stl"/>
      </geometry>
    </collision>
    <inertial>
      <mass value="0.8" />
      <origin xyz="0.0 0.0 0.08535" rpy="0 0 0" />
      <inertia ixx="0.002084999166" ixy="0.0" ixz="0.0"
        iyy="0.002084999166" iyz="0.0"
        izz="0.00225" />
    </inertial>
  </link>

  <joint name="wrist_3_joint" type="revolute">
    <parent link="wrist_2_link" />
    <child link = "wrist_3_link" />
    <origin xyz="0.0 0.0819 0.0" rpy="1.57 3.14 3.14" />
    <axis xyz="0 0 1" />
    <limit lower="-6.28" upper="6.28" effort="12.0" velocity="6.28"/>
    <dynamics damping="0.0" friction="0.0"/>
  </joint>

  <link name="wrist_3_link">
    <visual>
      <origin xyz="0 0 -0.082" rpy="1.57 0 0"/>
      <geometry>
        <mesh filename="visual/wrist3.dae"/>
      </geometry>
      <material name="LightGrey">
        <color rgba="0.7 0.7 0.7 1.0"/>
      </material>
    </visual>
    <collision>
      <origin xyz="0.0 0.0619 0.0" rpy="1.57 0 0" />
      <geometry>
        <mesh filename="collision/wrist3.stl"/>
      </geometry>
    </collision>
    <inertial>
      <mass value="0.35" />
      <inertia ixx="0.00013626661216" ixy="0.0" ixz="0.0"
        iyy="0.00013626661216" iyz="0.0"
        izz="0.0001792" />
    </inertial>
  </link>

</robot>
